Workbook

Sheet Cómo completar
B2: PosadasVive · carga de datos
B3: Una sola lista de lugares. Cada lugar puede estar en varias categorías: así funcionan los filtros combinables de la web.
B5: Hojas
B6: Lugares | C6: Todo lo que se muestra en la web: museos, bares, parques, paseos guiados, excursiones. Una fila por lugar, aunque esté en varias categorías.
B7: Agenda | C7: Las fechas: cada salida de un paseo guiado y cada evento puntual (un show, una feria). Una fila por fecha.
B8: Categorías | C8: Lista de categorías y subcategorías válidas, para consultar.
B10: Hoja Lugares
B11: ID | C11: Código corto que usa la web. NO cambiar los que ya están. Para lugares nuevos se puede dejar vacío: se genera solo a partir del nombre.
B12: Publicar | C12: "Sí" o "No". Con "No" el lugar queda en la planilla pero no sale en la web (por ejemplo, mientras faltan datos).
B13: Tipo | C13: Lugar: se puede visitar cualquier día (museo, bar, parque). Actividad: tiene fechas, como los paseos guiados. Sus fechas van en la hoja Agenda. Excursión: la vende una agencia y se consulta (los "Paquetes").
B14: Categorías | C14: Columnas Cultura a Excursiones: marcar con X todas las que correspondan. Un restaurante con espectáculos lleva X en Gastronomía y en Vida nocturna.
B15: Subcategorías | C15: Opcional, separadas por coma. Ver la hoja Categorías (por ejemplo: Pescados, Bares).
B16: Coordenadas | C16: Las que da Google Maps al tocar el lugar, tal cual: -27.3579, -55.8911. Sin coordenadas el lugar sale en la lista pero no en el mapa.
B17: Teléfono / WhatsApp | C17: Teléfono con código de área. En WhatsApp poner "Sí" solo si ese número atiende por WhatsApp: la web muestra el botón.
B18: Inscripción | C18: Solo para actividades: "Gratis con inscripción" (con Cupo), "Paga (reserva por WhatsApp)" o vacío.
B19: Descripción / Recomendación | C19: La descripción es el texto de la ficha. La recomendación sale destacada como dato útil ("Llegá antes del atardecer").
B20: Foto | C20: Enlace a una imagen (de Drive con acceso público, o de la web del lugar). Sin foto se muestra el ícono de la categoría.
B21: Portugués | C21: Opcional. Si se completa, la web lo usa cuando el visitante elige portugués.
B22: Observaciones | C22: Notas internas, no se publican. Ahí marcamos lo que falta en cada fila.
B24: Hoja Agenda
B25: Fecha y Hora | C25: Fecha dd/mm/aaaa. Hora 17:00. Si todavía no está, dejar la hora vacía y poner Estado "A confirmar".
B26: ID | C26: El ID de la actividad en la hoja Lugares. La columna de al lado muestra el nombre, para verificar que sea el correcto.
B27: Nombre del evento | C27: Solo para eventos puntuales en un lugar (un show en un teatro): ID del lugar + nombre del evento. Para paseos guiados, dejarlo vacío.
B29: Para mandar los datos
B30: Formato | C30: Alcanza con mandar este mismo archivo .xlsx. Si prefieren CSV: exportar las hojas Lugares y Agenda por separado (Archivo > Descargar > CSV).
B31: Lo que se revisa | C31: Al cargar, un programa revisa IDs repetidos, coordenadas fuera de Misiones, teléfonos mal escritos y fechas inválidas, y devuelve la lista de correcciones.
B33: Celdas para completar
C34: Blanco: datos para completar o corregir.
C35: Amarillo: Observaciones, lo que falta en esa fila.
C36: Gris: se completa solo, no hace falta tocarlo.
B38: Los datos ya cargados vienen de la planilla que nos pasaron, unificados: los lugares que estaban en varias pestañas (por ejemplo Holy, en Pescados, Parrillas y Bares) ahora son una sola fila con varias categorías.

Sheet Lugares
A1: ID | B1: Publicar | C1: Tipo | D1: Nombre | E1: Cultura | F1: Naturaleza | G1: Paseo guiado | H1: Náutico | I1: Gastronomía | J1: Vida nocturna | K1: Niños | L1: Excursiones | M1: Subcategorías | N1: Dirección | O1: Coordenadas | P1: Link Google Maps | Q1: Teléfono | R1: WhatsApp | S1: Instagram | T1: Web / más info | U1: Horario | V1: Precio | W1: Inscripción | X1: Cupo | Y1: Organiza | Z1: Descripción | AA1: Recomendación | AB1: Foto (link) | AC1: Nombre (portugués) | AD1: Descripción (portugués) | AE1: Observaciones (no se publica)
A2: auditorio-edr | B2: Sí | C2: Lugar | D2: Auditorio EDR | E2: X | M2: Salas culturales | N2: 3 de Febrero 1660 | P2: https://maps.app.goo.gl/jUvg9vRG75Kmg52n8 | Q2: +54 9 376 480-6272 | S2: https://www.instagram.com/auditorioedr/ | AE2: Falta coordenadas (sin ellas no aparece en el mapa)
A3: auditorio-fundacion-grillos | B3: Sí | C3: Lugar | D3: Auditorio Fundación Grillos | E3: X | M3: Salas culturales | N3: Cte. Miño 2418 | P3: https://maps.app.goo.gl/xGMffyTsaJwsH3B38 | S3: https://www.instagram.com/fundaciongrillos/ | AE3: Falta coordenadas (sin ellas no aparece en el mapa)
A4: catedral | B4: Sí | C4: Lugar | D4: Catedral San José | E4: X | N4: Plaza 9 de Julio, centro | O4: -27.365946, -55.894015 | U4: Todos los días · Entrada libre | V4: Gratis | Z4: Frente a la Plaza 9 de Julio se levanta la Catedral de Posadas, el edificio que marca el kilómetro cero de la ciudad. Sus torres blancas dominan el skyline del centro y adentro guarda un silencio fresco perfecto para hacer una pausa entre paseo y paseo. | AA4: La plaza y la catedral forman el núcleo fundacional: alrededor de esta manzana se organizó toda la Posadas del siglo XIX. | AB4: https://public.youware.com/users-website-assets/prod/d9801d5e-b9a5-4695-925c-d937bff38a4f/ed4d7756d242411e9051c9c98c76af25 | AC4: Catedral San José | AD4: Em frente à Praça 9 de Julio fica a Catedral de Posadas, o prédio que marca o marco zero da cidade. Suas torres brancas dominam o horizonte do centro e lá dentro há um silêncio fresco, perfeito para uma pausa entre um passeio e outro.
A5: centro-artistico-mandove-pedrozo | B5: Sí | C5: Lugar | D5: Centro Artístico Mandove Pedrozo | E5: X | M5: Salas culturales | N5: Beethoven 1762 | O5: -27.3654297, -55.9039132 | P5: https://maps.app.goo.gl/4VZgBYWCivZw6L1g7 | Q5: +54 9 376 463-5014 | S5: https://www.instagram.com/mandoveteatro/
A6: centro-cultural-comunitario-el-galpon-de | B6: Sí | C6: Lugar | D6: Centro Cultural Comunitario “El Galpón” de la Murga de la Estación | E6: X | M6: Salas culturales | N6: Av. Trincheras de San José 1709 | P6: https://maps.app.goo.gl/BmCiQDVdskGu3JQx5 | S6: https://www.instagram.com/murgadelaestacion/ | AE6: Falta coordenadas (sin ellas no aparece en el mapa)
A7: centro-cultural-vicente-cidade | B7: Sí | C7: Lugar | D7: Centro Cultural Vicente Cidade | E7: X | M7: Salas culturales | N7: Belgrano 1345 | O7: -27.3636881, -55.8879635 | P7: https://maps.app.goo.gl/CTUzeaj6Mgh9X5778 | Q7: +54 376 444-7355 | S7: https://www.instagram.com/centroculturalcidade/
A8: espacio-base | B8: Sí | C8: Lugar | D8: Espacio Base | E8: X | M8: Salas culturales | N8: Av. Rademacher 5324 | P8: https://maps.app.goo.gl/1ycWczSDrW54RsER8 | S8: https://www.instagram.com/espacio_base/ | AE8: Falta coordenadas (sin ellas no aparece en el mapa)
A9: espacio-reciclado | B9: Sí | C9: Lugar | D9: Espacio Reciclado | E9: X | M9: Salas culturales | N9: Av. Trincheras de San José y Misiones | P9: https://maps.app.goo.gl/qPtLkPn18Ax4oAtg7 | S9: https://www.instagram.com/espacio_recicladoo/ | AE9: Falta coordenadas (sin ellas no aparece en el mapa)
A10: flora-espacio-cultural | B10: Sí | C10: Lugar | D10: Flora - Espacio Cultural | E10: X | M10: Salas culturales | N10: Sta. Fe 1531 | P10: https://maps.app.goo.gl/MHT1sP26N7jdHS8YA | AE10: Falta coordenadas (sin ellas no aparece en el mapa)
A11: museo-historico-policial | B11: Sí | C11: Lugar | D11: Museo Histórico Policial | E11: X | M11: Museos | N11: Felix de Azara 2432 | P11: https://maps.app.goo.gl/ZqwqRfKe41yBgZFF8 | Q11: +54 376 444-7662 | AE11: Falta coordenadas (sin ellas no aparece en el mapa)
A12: museo-historico-y-arqueologico-andres-gu | B12: Sí | C12: Lugar | D12: Museo Histórico y Arqueológico “Andrés Guacurarí” | E12: X | M12: Museos | N12: Gral. Paz 1865 | P12: https://maps.app.goo.gl/frnL9sNvLrksPEvn6 | Q12: +54 376 444-7373 | S12: https://www.instagram.com/museoguacurari/ | AE12: Falta coordenadas (sin ellas no aparece en el mapa)
A13: museo-provincial-de-bellas-artes-juan-ya | B13: Sí | C13: Lugar | D13: Museo Provincial de Bellas Artes “Juan Yaparí” | E13: X | M13: Museos | N13: Sarmiento 1885 | P13: https://maps.app.goo.gl/vgZe2p9fQnBfSDng8 | Q13: +54 376 444-7616 | S13: https://www.instagram.com/juanyapari/ | AE13: Falta coordenadas (sin ellas no aparece en el mapa)
A14: museo-regional-anibal-cambas | B14: Sí | C14: Lugar | D14: Museo Regional “Aníbal Cambas” | E14: X | M14: Museos | N14: Alberdi 600 | P14: https://maps.app.goo.gl/jP7VFtriKcM6W7Zx7 | Q14: +54 9 376 414-5673 | S14: https://www.instagram.com/museocambas/ | AE14: Falta coordenadas (sin ellas no aparece en el mapa)
A15: museo-de-ciencias-naturales-e-historia-a | B15: Sí | C15: Lugar | D15: Museo de Ciencias Naturales e Historia “Antonio Ruiz de Montoya” | E15: X | M15: Museos | N15: Av. Balcarce y calle 31 a (Jardín Botánico Alberto Roth) | O15: -27.408679, -55.896763 | P15: https://maps.app.goo.gl/CzUNNJDy2wrubzDfA | AE15: Coordenadas aproximadas: las del Jardín Botánico
A16: palacio-del-mate-museo-municipal-de-bell | B16: Sí | C16: Lugar | D16: Palacio del Mate / Museo Municipal de Bellas Artes “Lucas Braulio Areco” | E16: X | M16: Museos | N16: Rivadavia 1846 | O16: -27.3675977, -55.8917275 | P16: https://maps.app.goo.gl/NcZsyCa5f1Bt3qXF9 | Q16: +54 9 376 530-3192 | S16: https://www.instagram.com/museolucasbraulioareco/
A17: conocimiento | B17: Sí | C17: Lugar | D17: Parque del Conocimiento | E17: X | K17: X | M17: Salas culturales | N17: Av. Ulises López | O17: -27.395143, -55.963822 | P17: https://maps.app.goo.gl/FmBLQmzNLPPiBZLt9 | Q17: +54 376 459-7565 | S17: https://www.instagram.com/parqueconocimiento/ | U17: Según cartelera · Ver funciones | V17: Según función | W17: Paga (reserva por WhatsApp) | Z17: Un complejo cultural imponente que ilumina la noche posadeña: el Teatro Lírico, el planetario, la biblioteca y salas de muestras. De día un paseo familiar, de noche un plan de espectáculos, conciertos y cine bajo las estrellas del planetario. | AA17: El Parque del Conocimiento alberga uno de los teatros líricos más modernos del norte argentino, con acústica de nivel internacional. | AB17: https://public.youware.com/users-website-assets/prod/d9801d5e-b9a5-4695-925c-d937bff38a4f/09f382909b3f4d4eb422103cbaf60fee | AD17: Um complexo cultural imponente que ilumina a noite de Posadas: o Teatro Lírico, o planetário, a biblioteca e salas de exposição. De dia um passeio em família, à noite um programa de espetáculos, shows e sessões sob as estrelas do planetário.
A18: teatro-nirvana | B18: Sí | C18: Lugar | D18: Teatro Nirvana | E18: X | M18: Salas culturales | N18: Av. Martín Fierro 5129 | P18: https://maps.app.goo.gl/QBJ48FA24dz4Z6NL9 | Q18: +54 9 376 436-5792 | S18: https://www.instagram.com/nirvana._.teatro/ | AE18: Falta coordenadas (sin ellas no aparece en el mapa)
A19: teatro-sala-tempo | B19: Sí | C19: Lugar | D19: Teatro Sala Tempo | E19: X | M19: Salas culturales | N19: Ramón García 554 | O19: -27.3546314, -55.896275 | P19: https://maps.app.goo.gl/mBuM1s4D58DRBgBA6 | S19: https://www.instagram.com/salatempo.ok/
A20: jardin-botanico | B20: Sí | C20: Lugar | D20: Jardín Botánico Alberto Roth | F20: X | N20: Av. Balcarce y calle 31 a | O20: -27.408679, -55.896763 | P20: https://maps.app.goo.gl/aQe8DKUMgMBm8gP97 | S20: https://www.instagram.com/jardinbotanicoposadas/
A21: costanera | B21: Sí | C21: Lugar | D21: Mates en la Costanera | F21: X | N21: Costanera Monseñor Kemerer | O21: -27.361009, -55.889051 | U21: Siempre abierta · Gratis | V21: Gratis | Z21: No hay plan más posadeño que sentarse en el pasto de la Costanera con el termo bajo el brazo. Al atardecer se llena de familias, ciclistas y grupos cebando mate frente al río. Traé reposera y disfrutá el show del cielo. | AA21: La Costanera tiene más de 15 km sobre el Paraná. La ampliación borró para siempre las viejas casas del río, pero la Bajada Vieja quedó como testigo. | AB21: https://public.youware.com/users-website-assets/prod/d9801d5e-b9a5-4695-925c-d937bff38a4f/7ce22f5cf01549289eb4a7d776a8e035 | AC21: Mate na Costanera | AD21: Não há programa mais posadeño do que sentar na grama da Costanera com a garrafa térmica debaixo do braço. Ao entardecer ela se enche de famílias, ciclistas e grupos tomando mate de frente para o rio. Leve uma cadeira de praia e aproveite o espetáculo do céu.
A22: parque-la-cascada | B22: Sí | C22: Lugar | D22: Parque La Cascada | F22: X | N22: Av. Costanera | P22: https://maps.app.goo.gl/BmEZKGDGNKC7brr88 | AE22: Falta coordenadas (sin ellas no aparece en el mapa)
A23: parque-paraguay | B23: Sí | C23: Lugar | D23: Parque República del Paraguay | F23: X | K23: X | N23: Roque González 500-598 | O23: -27.354927, -55.893647 | P23: https://maps.app.goo.gl/6TPqJQ631F1wb49w8
A24: parque-de-la-ciudad | B24: Sí | C24: Lugar | D24: Parque de La Ciudad | F24: X | N24: RN12 1335 | P24: https://maps.app.goo.gl/ZfdZhoT3AhqM2Smh9 | S24: https://www.instagram.com/parquedelaciudad_posadas/ | AE24: Falta coordenadas (sin ellas no aparece en el mapa)
A25: brete | B25: Sí | C25: Lugar | D25: Playa El Brete | F25: X | N25: Zona norte, sobre el Paraná | O25: -27.354086, -55.902548 | U25: Verano · Playa urbana | V25: Gratis | Z25: La playa urbana de Posadas: arena sobre el Paraná donde los posadeños se refrescan en verano. Sombrillas, mate, gurises jugando en la orilla y el río tibio como pileta natural. Un plan clásico para las tardes de calor misionero. | AA25: El Brete es una de las pocas playas de río habilitadas dentro del ejido urbano de una capital argentina. Ciudad y naturaleza, todo junto. | AB25: https://public.youware.com/users-website-assets/prod/d9801d5e-b9a5-4695-925c-d937bff38a4f/6a4619b9ea2a4d9a91273d4cac1d5bc1 | AC25: Praia El Brete | AD25: A praia urbana de Posadas: areia às margens do Paraná, onde os moradores se refrescam no verão. Guarda-sóis, mate, crianças brincando na beira e o rio morno como piscina natural. Um programa clássico para as tardes de calor missioneiro.
A26: reserva-natural-urbana-arroyo-ita | B26: Sí | C26: Lugar | D26: Reserva Natural Urbana “Arroyo Itá” | F26: X | N26: Av. Justo José de Urquiza 3494-3686 | P26: https://maps.app.goo.gl/ghM9GTzgvgJLcWFq9 | Q26: +54 9 376 453-8249 | AE26: Falta coordenadas (sin ellas no aparece en el mapa)
A27: reserva-natural-urbana-rincon-nazari | B27: Sí | C27: Lugar | D27: Reserva Natural Urbana “Rincón Nazarí” | F27: X | N27: Brasil 3409 | P27: https://maps.app.goo.gl/8ujuhu2ocfNBph5L6 | AE27: Falta coordenadas (sin ellas no aparece en el mapa)
A28: mirador | B28: Sí | C28: Lugar | D28: Vista al Puente San Roque | F28: X | N28: Costanera, tramo norte | O28: -27.352, -55.885 | U28: Mejor al atardecer | V28: Gratis | Z28: Desde este tramo de la Costanera se abre la mejor panorámica del Puente Internacional San Roque González de Santa Cruz, que une Argentina con Paraguay sobre el Paraná. Al atardecer, las luces de Encarnación empiezan a titilar del otro lado del agua. | AA28: El puente tiene 2,55 km de largo y conecta Posadas con Encarnación. Es uno de los pasos fronterizos más transitados del país. | AB28: https://public.youware.com/users-website-assets/prod/d9801d5e-b9a5-4695-925c-d937bff38a4f/df8cbcfd02d549468b69db33d009495b | AC28: Vista da Ponte San Roque | AD28: Deste trecho da Costanera se tem a melhor vista da Ponte Internacional San Roque González de Santa Cruz, que une a Argentina ao Paraguai sobre o Paraná. Ao entardecer, as luzes de Encarnación começam a piscar do outro lado da água.
A29: cementerio | B29: Sí | C29: Actividad | D29: Cementerio Nocturno | E29: X | G29: X | N29: Cementerio La Piedad | O29: -27.379564, -55.912587 | W29: Gratis con inscripción | X29: 20 | Z29: Un paseo entre mausoleos a la luz de faroles, donde la historia de Posadas se cruza con sus mitos. Personajes ilustres, leyendas del río y arquitectura funeraria de otro siglo. No es de terror: es memoria y patrimonio. | AA29: Los antiguos cementerios de las capitales provinciales son verdaderos museos a cielo abierto: sus mausoleos cuentan quién fundó y dio forma a la ciudad. | AB29: https://public.youware.com/users-website-assets/prod/d9801d5e-b9a5-4695-925c-d937bff38a4f/578538ec9a874dc4a02c43101eb5233f | AC29: Cemitério à Noite | AD29: Um passeio entre mausoléus à luz de lampiões, onde a história de Posadas se cruza com seus mitos. Personagens ilustres, lendas do rio e arquitetura funerária de outro século. Não é de terror: é memória e patrimônio. | AE29: En la pestaña PG: “nombre a confirmar + EVENTO”
A30: murales | B30: Sí | C30: Actividad | D30: Murales en Bici + Luna Llena | E30: X | G30: X | N30: Punto EcoBicis, Costanera | O30: -27.369821, -55.885709 | W30: Gratis con inscripción | X30: 25 | Z30: Pedaleá la ciudad de noche recorriendo los murales que le dan color a Posadas, justo bajo la luna llena. Un circuito de arte urbano que conecta más de 60 intervenciones repartidas por los barrios. | AA30: Posadas ya registra más de 60 murales urbanos. El arte callejero transformó paredones grises en una galería a cielo abierto. | AB30: https://public.youware.com/users-website-assets/prod/d9801d5e-b9a5-4695-925c-d937bff38a4f/75def1ac6a6948edb582ad988b881b0f.jpeg | AC30: Murais de Bike + Lua Cheia | AD30: Pedale pela cidade à noite percorrendo os murais que colorem Posadas, bem debaixo da lua cheia. Um circuito de arte urbana que liga mais de 60 intervenções espalhadas pelos bairros. | AE30: Fue el 25/09. Si se repite, cargar la fecha en Agenda
A31: bajada | B31: Sí | C31: Actividad | D31: Paseo: Bajada Vieja | E31: X | G31: X | N31: Monumento a Andrés Guacurarí | O31: -27.360522, -55.887827 | W31: Gratis con inscripción | X31: 20 | Z31: El barrio del Mensú, la puerta de entrada original a la ciudad por el río. Adoquines, escalinatas y la historia de los trabajadores del yerbatal que marcaron la identidad de Misiones. El rincón que dio origen a Posadas. | AA31: La Bajada Vieja es el único tramo del casco antiguo que sobrevivió a la ampliación de la Costanera: un pedazo de la Posadas de 1900 intacto. | AB31: https://public.youware.com/users-website-assets/prod/d9801d5e-b9a5-4695-925c-d937bff38a4f/dba54949e8ea4575969059e4eab819cc.jpg | AC31: Passeio: Bajada Vieja | AD31: O bairro do Mensú, a porta de entrada original da cidade pelo rio. Paralelepípedos, escadarias e a história dos trabalhadores dos ervais que marcaram a identidade de Misiones. O cantinho que deu origem a Posadas. | AE31: La app lo muestra los domingos 16 hs; en la pestaña PG figura un sábado
A32: biofabrica | B32: Sí | C32: Actividad | D32: Paseo: Biofábrica | F32: X | G32: X | AE32: Falta punto de encuentro y descripción. Revisar categorías
A33: casco | B33: Sí | C33: Actividad | D33: Paseo: Casco Histórico | E33: X | G33: X | N33: Punto de encuentro: Plaza 9 de Julio | O33: -27.366, -55.8965 | W33: Gratis con inscripción | X33: 20 | Z33: Una caminata guiada por el corazón fundacional de Posadas. Arranca en la Plaza 9 de Julio, frente a la Catedral, y recorre los edificios que cuentan cómo una aldea a orillas del Paraná se transformó en capital provincial. | AA33: Posadas se llamó "Trinchera de San José" antes de adoptar su nombre actual en homenaje a Gervasio Antonio de Posadas, primer Director Supremo de las Provincias Unidas. | AB33: https://public.youware.com/users-website-assets/prod/d9801d5e-b9a5-4695-925c-d937bff38a4f/1ba0b659ee4d45ebbc04932f16bbf5eb.jpg | AC33: Passeio: Centro Histórico | AD33: Uma caminhada guiada pelo coração da fundação de Posadas. Começa na Praça 9 de Julio, em frente à Catedral, e percorre os prédios que contam como uma aldeia às margens do Paraná virou capital de província. | AE33: No figura en la pestaña PG de julio. La app lo muestra los sábados 16 hs: confirmar
A34: de-las-artes | B34: Sí | C34: Actividad | D34: Paseo: De las Artes | E34: X | G34: X | AE34: Falta punto de encuentro y descripción. Revisar categorías
A35: jardin | B35: Sí | C35: Actividad | D35: Paseo: Jardín Botánico | F35: X | G35: X | N35: SUM del Jardín Botánico A. Roth | O35: -27.408679, -55.896763 | W35: Gratis con inscripción | X35: 30 | Z35: Un recorrido guiado por el pulmón verde de la ciudad. Especies nativas de la selva misionera, senderos a la sombra y un guardián que te cuenta el legado de Alberto Roth, el creador de este oasis urbano. | AA35: El Jardín Botánico de Posadas ya superó los 45 años. Conserva especies de la selva paranaense que hoy escasean en estado silvestre. | AB35: https://public.youware.com/users-website-assets/prod/d9801d5e-b9a5-4695-925c-d937bff38a4f/956cf2fe09b245cdb459b6f1d833f7de.jpeg | AC35: Passeio: Jardim Botânico | AD35: Um passeio guiado pelo pulmão verde da cidade. Espécies nativas da mata missioneira, trilhas na sombra e um guia que conta o legado de Alberto Roth, o criador deste oásis urbano. | AE35: La pestaña PG dice domingos 17 hs; la app tenía 16 hs. Se corrige al cargar las fechas en Agenda
A36: parque | B36: Sí | C36: Actividad | D36: Paseo: Parque Paraguayo | E36: X | F36: X | G36: X | N36: Frente al Museo Aníbal Cambas | O36: -27.355543, -55.89355 | W36: Gratis con inscripción | X36: 30 | Z36: Un paseo por el parque que homenajea la hermandad con el Paraguay, a pasos del río. Monolitos, especies añosas y el Museo Aníbal Cambas al lado para completar la mañana con historia regional. | AA36: El nombre del parque refleja el vínculo profundo entre Posadas y Encarnación: dos ciudades hermanas separadas apenas por el ancho del Paraná. | AB36: https://public.youware.com/users-website-assets/prod/d9801d5e-b9a5-4695-925c-d937bff38a4f/068282e1e2994c28bc1d999bd825d687.jpg | AC36: Passeio: Parque Paraguaio | AD36: Um passeio pelo parque que homenageia a irmandade com o Paraguai, a poucos passos do rio. Monólitos, árvores centenárias e o Museu Aníbal Cambas ao lado para completar a manhã com história regional. | AE36: En la pestaña PG: “Historia y Tradición”, viernes 17 hs. La app tenía domingos 10 hs
A37: peste-bubonica | B37: Sí | C37: Actividad | D37: Paseo: Peste Bubónica | E37: X | G37: X | AE37: Falta punto de encuentro y descripción. Revisar categorías
A38: por-los-templos | B38: Sí | C38: Actividad | D38: Paseo: Por los Templos | E38: X | G38: X | AE38: Falta punto de encuentro y descripción. Revisar categorías
A39: puertas-abiertas | B39: Sí | C39: Actividad | D39: Paseo: Puertas Abiertas | E39: X | G39: X | AE39: Falta punto de encuentro y descripción. Revisar categorías
A40: catamaran | B40: Sí | C40: Actividad | D40: Paseos en Catamarán “Misión Paraná” | H40: X | N40: Muelle 4to tramo, Costanera | O40: -27.3591, -55.8893 | V40: Desde $4.500 | W40: Paga (reserva por WhatsApp) | Z40: El clásico posadeño de manual: subirse al catamarán cuando el sol se hunde detrás de Encarnación y el Paraná se pinta de naranja. Cuarenta minutos de río, camalotes flotando y la mejor postal del Puente San Roque González. | AA40: El río Paraná es el segundo más largo de Sudamérica. Desde acá ves dos países en una sola foto: Argentina y Paraguay. | AB40: https://public.youware.com/users-website-assets/prod/d9801d5e-b9a5-4695-925c-d937bff38a4f/466b6076366545c5841f3708a9fbc7ae.jpg | AD40: O clássico de Posadas: embarcar no catamarã quando o sol se põe atrás de Encarnación e o Paraná fica laranja. Quarenta minutos de rio, aguapés flutuando e o melhor cartão-postal da Ponte San Roque González. | AE40: En la planilla figura como Paseos en Catamarán “Misión Paraná”. La app lo muestra todos los días 18:30: confirmar horario y precio
...

Sheet Agenda
A1: Fecha | B1: Hora | C1: ID | D1: Nombre según ID (automático) | E1: Nombre del evento (solo eventos puntuales) | F1: Estado | G1: Punto de encuentro | H1: Cupo | I1: Notas (no se publica)
A2: 46213 | B2: 17:00 | C2: parque | D2: =IF(C2="","",IFERROR(INDEX(Lugares!$D$2:$D$600,MATCH(C2,Lugares!$A$2:$A$600,0)),"⚠ ID no encontrado")) -> Paseo: Parque Paraguayo | F2: Confirmado | I2: Ejemplo: julio, de la pestaña PG original
A3: 46214 | C3: cementerio | D3: =IF(C3="","",IFERROR(INDEX(Lugares!$D$2:$D$600,MATCH(C3,Lugares!$A$2:$A$600,0)),"⚠ ID no encontrado")) -> Cementerio Nocturno | F3: A confirmar | I3: Ejemplo: julio, de la pestaña PG original (decía "+ EVENTO") (nombre a confirmar)
A4: 46215 | B4: 17:00 | C4: jardin | D4: =IF(C4="","",IFERROR(INDEX(Lugares!$D$2:$D$600,MATCH(C4,Lugares!$A$2:$A$600,0)),"⚠ ID no encontrado")) -> Paseo: Jardín Botánico | F4: Confirmado | I4: Ejemplo: julio, de la pestaña PG original
A5: 46218 | C5: puertas-abiertas | D5: =IF(C5="","",IFERROR(INDEX(Lugares!$D$2:$D$600,MATCH(C5,Lugares!$A$2:$A$600,0)),"⚠ ID no encontrado")) -> Paseo: Puertas Abiertas | F5: A confirmar | I5: Ejemplo: julio, de la pestaña PG original
A6: 46219 | B6: 16:30 | C6: peste-bubonica | D6: =IF(C6="","",IFERROR(INDEX(Lugares!$D$2:$D$600,MATCH(C6,Lugares!$A$2:$A$600,0)),"⚠ ID no encontrado")) -> Paseo: Peste Bubónica | F6: Confirmado | I6: Ejemplo: julio, de la pestaña PG original
A7: 46220 | B7: 09:00 | C7: biofabrica | D7: =IF(C7="","",IFERROR(INDEX(Lugares!$D$2:$D$600,MATCH(C7,Lugares!$A$2:$A$600,0)),"⚠ ID no encontrado")) -> Paseo: Biofábrica | F7: Confirmado | I7: Ejemplo: julio, de la pestaña PG original
A8: 46221 | B8: 14:30 | C8: por-los-templos | D8: =IF(C8="","",IFERROR(INDEX(Lugares!$D$2:$D$600,MATCH(C8,Lugares!$A$2:$A$600,0)),"⚠ ID no encontrado")) -> Paseo: Por los Templos | F8: Confirmado | I8: Ejemplo: julio, de la pestaña PG original
A9: 46225 | C9: de-las-artes | D9: =IF(C9="","",IFERROR(INDEX(Lugares!$D$2:$D$600,MATCH(C9,Lugares!$A$2:$A$600,0)),"⚠ ID no encontrado")) -> Paseo: De las Artes | F9: A confirmar | I9: Ejemplo: julio, de la pestaña PG original
A10: 46227 | B10: 17:00 | C10: parque | D10: =IF(C10="","",IFERROR(INDEX(Lugares!$D$2:$D$600,MATCH(C10,Lugares!$A$2:$A$600,0)),"⚠ ID no encontrado")) -> Paseo: Parque Paraguayo | F10: Confirmado | I10: Ejemplo: julio, de la pestaña PG original
A11: 46228 | C11: bajada | D11: =IF(C11="","",IFERROR(INDEX(Lugares!$D$2:$D$600,MATCH(C11,Lugares!$A$2:$A$600,0)),"⚠ ID no encontrado")) -> Paseo: Bajada Vieja | F11: A confirmar | I11: Ejemplo: julio, de la pestaña PG original
A12: 46229 | B12: 17:00 | C12: jardin | D12: =IF(C12="","",IFERROR(INDEX(Lugares!$D$2:$D$600,MATCH(C12,Lugares!$A$2:$A$600,0)),"⚠ ID no encontrado")) -> Paseo: Jardín Botánico | F12: Confirmado | I12: Ejemplo: julio, de la pestaña PG original
A13: 46232 | C13: puertas-abiertas | D13: =IF(C13="","",IFERROR(INDEX(Lugares!$D$2:$D$600,MATCH(C13,Lugares!$A$2:$A$600,0)),"⚠ ID no encontrado")) -> Paseo: Puertas Abiertas | F13: A confirmar | I13: Ejemplo: julio, de la pestaña PG original
A14: 46234 | B14: 09:00 | C14: biofabrica | D14: =IF(C14="","",IFERROR(INDEX(Lugares!$D$2:$D$600,MATCH(C14,Lugares!$A$2:$A$600,0)),"⚠ ID no encontrado")) -> Paseo: Biofábrica | F14: Confirmado | I14: Ejemplo: julio, de la pestaña PG original
D15: =IF(C15="","",IFERROR(INDEX(Lugares!$D$2:$D$600,MATCH(C15,Lugares!$A$2:$A$600,0)),"⚠ ID no encontrado"))
D16: =IF(C16="","",IFERROR(INDEX(Lugares!$D$2:$D$600,MATCH(C16,Lugares!$A$2:$A$600,0)),"⚠ ID no encontrado"))
D17: =IF(C17="","",IFERROR(INDEX(Lugares!$D$2:$D$600,MATCH(C17,Lugares!$A$2:$A$600,0)),"⚠ ID no encontrado"))
D18: =IF(C18="","",IFERROR(INDEX(Lugares!$D$2:$D$600,MATCH(C18,Lugares!$A$2:$A$600,0)),"⚠ ID no encontrado"))
D19: =IF(C19="","",IFERROR(INDEX(Lugares!$D$2:$D$600,MATCH(C19,Lugares!$A$2:$A$600,0)),"⚠ ID no encontrado"))
D20: =IF(C20="","",IFERROR(INDEX(Lugares!$D$2:$D$600,MATCH(C20,Lugares!$A$2:$A$600,0)),"⚠ ID no encontrado"))
D21: =IF(C21="","",IFERROR(INDEX(Lugares!$D$2:$D$600,MATCH(C21,Lugares!$A$2:$A$600,0)),"⚠ ID no encontrado"))
D22: =IF(C22="","",IFERROR(INDEX(Lugares!$D$2:$D$600,MATCH(C22,Lugares!$A$2:$A$600,0)),"⚠ ID no encontrado"))
D23: =IF(C23="","",IFERROR(INDEX(Lugares!$D$2:$D$600,MATCH(C23,Lugares!$A$2:$A$600,0)),"⚠ ID no encontrado"))
D24: =IF(C24="","",IFERROR(INDEX(Lugares!$D$2:$D$600,MATCH(C24,Lugares!$A$2:$A$600,0)),"⚠ ID no encontrado"))
D25: =IF(C25="","",IFERROR(INDEX(Lugares!$D$2:$D$600,MATCH(C25,Lugares!$A$2:$A$600,0)),"⚠ ID no encontrado"))
D26: =IF(C26="","",IFERROR(INDEX(Lugares!$D$2:$D$600,MATCH(C26,Lugares!$A$2:$A$600,0)),"⚠ ID no encontrado"))
... D600: =IF(C600="","",IFERROR(INDEX(Lugares!$D$2:$D$600,MATCH(C600,Lugares!$A$2:$A$600,0)),"⚠ ID no encontrado"))

Sheet Categorías
A1: Categoría (columna) | B1: Subcategorías válidas | C1: Qué va acá
A2: Cultura | B2: Museos, Salas culturales | C2: Museos, teatros, salas y centros culturales.
A3: Naturaleza | B3: — | C3: Parques, reservas, jardín botánico, costanera, playas.
A4: Paseo guiado | B4: — | C4: Paseos guiados con fecha (los "PG"). Se combinan con la temática: un PG en el Jardín Botánico también es Naturaleza.
A5: Náutico | B5: — | C5: Experiencias en el río: catamarán, kayak, SUP, veleros.
A6: Gastronomía | B6: Pescados, Galetos y parrillas, Vinos, Internacional | C6: Restaurantes, cafés, cervecerías, ferias de productores.
A7: Vida nocturna | B7: Bares, Bowling | C7: Bares, boliches, bowling, espectáculos. Un restaurante con shows también va acá.
A8: Niños | B8: — | C8: Lugares y actividades pensados para chicos.
A9: Excursiones | B9: — | C9: Paquetes de agencias (salidas fuera de Posadas o city tours).
A11: Si necesitan una subcategoría nueva (por ejemplo "Cafés" o "Ferias"), avisen y la agregamos: la web la toma sola.
